{"uuid": "dcc89ce3-dec9-4887-902f-981620d04bb2", "children": ["d5b4c9bf-0c95-4e41-b4a4-0045963784b9"], "befores": [{"name": "random_user_data", "status": "passed", "steps": [{"name": "Создание нового пользователя", "status": "passed", "parameters": [{"name": "new_user", "value": "<data.data.User object at 0x0000029182823490>"}], "start": 1736344337609, "stop": 1736344337868}], "start": 1736344337609, "stop": 1736344337868}], "afters": [{"name": "random_user_data::0", "status": "broken", "statusDetails": {"message": "requests.exceptions.ConnectTimeout: HTTPSConnectionPool(host='stellarburgers.nomoreparties.site', port=443): Max retries exceeded with url: /api/auth/user (Caused by ConnectTimeoutError(<urllib3.connection.HTTPSConnection object at 0x00000291828B5F00>, 'Connection to stellarburgers.nomoreparties.site timed out. (connect timeout=None)'))\n", "trace": "  File \"C:\\Users\\Pasha\\AppData\\Local\\Packages\\PythonSoftwareFoundation.Python.3.10_qbz5n2kfra8p0\\LocalCache\\local-packages\\Python310\\site-packages\\allure_commons\\_allure.py\", line 221, in __call__\n    return self._fixture_function(*args, **kwargs)\n  File \"C:\\Users\\Pasha\\AppData\\Local\\Packages\\PythonSoftwareFoundation.Python.3.10_qbz5n2kfra8p0\\LocalCache\\local-packages\\Python310\\site-packages\\_pytest\\fixtures.py\", line 907, in _teardown_yield_fixture\n    next(it)\n  File \"C:\\Users\\Pasha\\Desktop\\Diplom\\Diplom_3\\conftest.py\", line 49, in random_user_data\n    AuthMethods.delete_user(user) # После работы тестов через API удаляем созданного пользователя.\n  File \"C:\\Users\\Pasha\\AppData\\Local\\Packages\\PythonSoftwareFoundation.Python.3.10_qbz5n2kfra8p0\\LocalCache\\local-packages\\Python310\\site-packages\\allure_commons\\_allure.py\", line 192, in impl\n    return func(*a, **kw)\n  File \"C:\\Users\\Pasha\\Desktop\\Diplom\\Diplom_3\\api\\methods\\auth_methods.py\", line 25, in delete_user\n    response = requests.delete(f'{BASE_URL}{AUTH_URL}user', json={'accessToken': user.access_token})\n  File \"C:\\Users\\Pasha\\AppData\\Local\\Packages\\PythonSoftwareFoundation.Python.3.10_qbz5n2kfra8p0\\LocalCache\\local-packages\\Python310\\site-packages\\requests\\api.py\", line 158, in delete\n    return request('delete', url, **kwargs)\n  File \"C:\\Users\\Pasha\\AppData\\Local\\Packages\\PythonSoftwareFoundation.Python.3.10_qbz5n2kfra8p0\\LocalCache\\local-packages\\Python310\\site-packages\\requests\\api.py\", line 60, in request\n    return session.request(method=method, url=url, **kwargs)\n  File \"C:\\Users\\Pasha\\AppData\\Local\\Packages\\PythonSoftwareFoundation.Python.3.10_qbz5n2kfra8p0\\LocalCache\\local-packages\\Python310\\site-packages\\requests\\sessions.py\", line 533, in request\n    resp = self.send(prep, **send_kwargs)\n  File \"C:\\Users\\Pasha\\AppData\\Local\\Packages\\PythonSoftwareFoundation.Python.3.10_qbz5n2kfra8p0\\LocalCache\\local-packages\\Python310\\site-packages\\requests\\sessions.py\", line 646, in send\n    r = adapter.send(request, **kwargs)\n  File \"C:\\Users\\Pasha\\AppData\\Local\\Packages\\PythonSoftwareFoundation.Python.3.10_qbz5n2kfra8p0\\LocalCache\\local-packages\\Python310\\site-packages\\requests\\adapters.py\", line 504, in send\n    raise ConnectTimeout(e, request=request)\n"}, "steps": [{"name": "Удаление пользователя", "status": "broken", "statusDetails": {"message": "requests.exceptions.ConnectTimeout: HTTPSConnectionPool(host='stellarburgers.nomoreparties.site', port=443): Max retries exceeded with url: /api/auth/user (Caused by ConnectTimeoutError(<urllib3.connection.HTTPSConnection object at 0x00000291828B5F00>, 'Connection to stellarburgers.nomoreparties.site timed out. (connect timeout=None)'))\n", "trace": "  File \"C:\\Users\\Pasha\\AppData\\Local\\Packages\\PythonSoftwareFoundation.Python.3.10_qbz5n2kfra8p0\\LocalCache\\local-packages\\Python310\\site-packages\\allure_commons\\_allure.py\", line 192, in impl\n    return func(*a, **kw)\n  File \"C:\\Users\\Pasha\\Desktop\\Diplom\\Diplom_3\\api\\methods\\auth_methods.py\", line 25, in delete_user\n    response = requests.delete(f'{BASE_URL}{AUTH_URL}user', json={'accessToken': user.access_token})\n  File \"C:\\Users\\Pasha\\AppData\\Local\\Packages\\PythonSoftwareFoundation.Python.3.10_qbz5n2kfra8p0\\LocalCache\\local-packages\\Python310\\site-packages\\requests\\api.py\", line 158, in delete\n    return request('delete', url, **kwargs)\n  File \"C:\\Users\\Pasha\\AppData\\Local\\Packages\\PythonSoftwareFoundation.Python.3.10_qbz5n2kfra8p0\\LocalCache\\local-packages\\Python310\\site-packages\\requests\\api.py\", line 60, in request\n    return session.request(method=method, url=url, **kwargs)\n  File \"C:\\Users\\Pasha\\AppData\\Local\\Packages\\PythonSoftwareFoundation.Python.3.10_qbz5n2kfra8p0\\LocalCache\\local-packages\\Python310\\site-packages\\requests\\sessions.py\", line 533, in request\n    resp = self.send(prep, **send_kwargs)\n  File \"C:\\Users\\Pasha\\AppData\\Local\\Packages\\PythonSoftwareFoundation.Python.3.10_qbz5n2kfra8p0\\LocalCache\\local-packages\\Python310\\site-packages\\requests\\sessions.py\", line 646, in send\n    r = adapter.send(request, **kwargs)\n  File \"C:\\Users\\Pasha\\AppData\\Local\\Packages\\PythonSoftwareFoundation.Python.3.10_qbz5n2kfra8p0\\LocalCache\\local-packages\\Python310\\site-packages\\requests\\adapters.py\", line 504, in send\n    raise ConnectTimeout(e, request=request)\n"}, "parameters": [{"name": "user", "value": "<data.data.User object at 0x0000029182823490>"}], "start": 1736344342193, "stop": 1736344363244}], "start": 1736344342193, "stop": 1736344363247}], "start": 1736344337609, "stop": 1736344363247}